{"links": {"self": {"href": "data/repositories/osrf/gzweb/issues/41/comments/11801739.json"}, "html": {"href": "#!/osrf/gzweb/issues/41#comment-11801739"}}, "issue": {"links": {"self": {"href": "data/repositories/osrf/gzweb/issues/41.json"}}, "type": "issue", "id": 41, "repository": {"links": {"self": {"href": "data/repositories/osrf/gzweb.json"}, "html": {"href": "#!/osrf/gzweb"}, "avatar": {"href": "data/bytebucket.org/ravatar/{3e2fc3f2-dc25-453b-9792-943c743d9b40}ts=1609263"}}, "type": "repository", "name": "gzweb", "full_name": "osrf/gzweb", "uuid": "{3e2fc3f2-dc25-453b-9792-943c743d9b40}"}, "title": "Deploy.sh errors on VM'ed Ubuntu 12.04"}, "content": {"raw": "Ah, that almost worked! It fixed the compile errors with gzcoarse, but it looks like there's still a problem when I try to download the models with the `-m` flag. If I run `deploy.sh` without the `-m`, everything builds just fine and I can run gzweb, but I don't have any models at all (I have the names of models, but they just all load as white boxes).\n\n\nIf I run it with the `-m` flag, I get this output at the end:\n\n`error [Errno 2] No such file or directory\nTraceback (most recent call last):\n  File \"./webify_models_v2.py\", line 44, in <module>\n    subprocess.check_call(cmd)\n  File \"/usr/lib/python2.7/subprocess.py\", line 506, in check_call\n    retcode = call(*popenargs, **kwargs)\n  File \"/usr/lib/python2.7/subprocess.py\", line 493, in call\n    return Popen(*popenargs, **kwargs).wait()\n  File \"/usr/lib/python2.7/subprocess.py\", line 679, in __init__\n    errread, errwrite)\n  File \"/usr/lib/python2.7/subprocess.py\", line 1249, in _execute_child\n    raise child_exception\nOSError: [Errno 2] No such file or directory`\n\nSo, one bug down, one to go!", "markup": "markdown", "html": "<p>Ah, that almost worked! It fixed the compile errors with gzcoarse, but it looks like there's still a problem when I try to download the models with the <code>-m</code> flag. If I run <code>deploy.sh</code> without the <code>-m</code>, everything builds just fine and I can run gzweb, but I don't have any models at all (I have the names of models, but they just all load as white boxes).</p>\n<p>If I run it with the <code>-m</code> flag, I get this output at the end:</p>\n<p><code>error [Errno 2] No such file or directory\nTraceback (most recent call last):\n  File \"./webify_models_v2.py\", line 44, in &lt;module&gt;\n    subprocess.check_call(cmd)\n  File \"/usr/lib/python2.7/subprocess.py\", line 506, in check_call\n    retcode = call(*popenargs, **kwargs)\n  File \"/usr/lib/python2.7/subprocess.py\", line 493, in call\n    return Popen(*popenargs, **kwargs).wait()\n  File \"/usr/lib/python2.7/subprocess.py\", line 679, in __init__\n    errread, errwrite)\n  File \"/usr/lib/python2.7/subprocess.py\", line 1249, in _execute_child\n    raise child_exception\nOSError: [Errno 2] No such file or directory</code></p>\n<p>So, one bug down, one to go!</p>", "type": "rendered"}, "created_on": "2014-08-15T00:59:36.774879+00:00", "user": {"display_name": "Nick Sweet", "uuid": "{7148c918-f4ee-4696-9a93-ca3d4d5ed22c}", "links": {"self": {"href": "https://api.bitbucket.org/2.0/users/%7B7148c918-f4ee-4696-9a93-ca3d4d5ed22c%7D"}, "html": {"href": "https://bitbucket.org/%7B7148c918-f4ee-4696-9a93-ca3d4d5ed22c%7D/"}, "avatar": {"href": "data/secure.gravatar.com/avatar/d0e268211e46eb31d9e39db0d8cffbcdd=httpsavatar-management--avatars.us-west-2.prod.public.atl-paas.netinitialsNS-1.png"}}, "nickname": "nckswt", "type": "user", "account_id": "557058:093cd9bd-573b-4137-8381-4e27226bb788"}, "updated_on": null, "type": "issue_comment", "id": 11801739}